Workbook

Sheet How to Write
A1: Rule | B1: Why
A2: Write every query BEFORE looking at the legacy KB cards. | B2: If you copy card wording, the old bot gets inflated scores.
A3: Write like a real stressed customer on a phone: short, lowercase, vague. | B3: Real users do not phrase things like FAQ headings.
A4: Clean paraphrase: same meaning as a real question, different words. | B4: Tests understanding of meaning, not keyword matching.
A5: Typos / slang: misspellings, abbreviations, no punctuation. | B5: Tests robustness.
A6: Spanish: write it in natural Spanish, the way a customer would type. | B6: The KB is English only. Tests cross-language answering.
A7: Ambiguous: could mean two things. Correct behavior is a clarifying question. | B7: e.g. "my bill is wrong" could be a dispute, high usage, or rates.
A8: Transactional: the customer wants something DONE, not explained. | B8: Correct behavior is routing to the right flow or link.
A9: Out of scope: commercial, account specific, other city services, totally unrelated. | B9: Correct behavior is a polite decline and a pointer.
A10: must_include: 1 to 3 key facts a correct answer MUST contain. | B10: This is how answers get graded. Take facts from the gold page.
A11: gold_page_ids is prefilled with every page tagged to that intent. Delete the ones that do not answer your specific query. | B11: Lets you check whether the bot cited the right page.
A13: EXAMPLES
A14: T: Report Outage / Transactional | B14: "lights are out on my whole street how do i tell you" -> route -> must_include: 512-322-9100 or text OUT to 287846
A15: T: Rebates / Clean paraphrase | B15: "do yall pay people back for buying a new ac unit" -> answer -> must_include: averaging $800; participating contractor
A16: T: Rebates / Spanish | B16: "hay algun reembolso por cambiar el aire acondicionado" -> answer -> must_include: averaging $800
A17: T: Understand My Bill / Ambiguous | B17: "why is my bill so high" -> clarify (usage vs rates vs error)
A18: T: Safety / Typos | B18: "pwr out agin wat do i do" -> answer -> must_include: check breakers OR report outage
A19: T: Out-of-Scope | B19: "my water pipe burst" -> decline -> point to Austin Water / 3-1-1
A20: T: Out-of-Scope | B20: "what is my account balance" -> decline -> no account access, log in to COA Utilities

Sheet Test Set
A1: query_id | B1: intent_group | C1: query_type | D1: query | E1: expected_behavior | F1: gold_page_ids | G1: must_include | H1: notes | I1: status | J1: your_original_query | K1: why_changed
A2: T001 | B2: Report Outage | C2: Transactional | D2: lights are out at my house how do i tell you | E2: route | F2: P01; P02; P03; P34; P35 | G2: 512-322-9100 OR text OUT to 287846 OR report online | I2: kept
A3: T002 | B3: Report Outage | C3: Transactional | D3: need to report a blackout | E3: route | F3: P01; P02; P03; P34; P35 | G3: 512-322-9100 OR text OUT to 287846 OR report online | I3: kept
A4: T003 | B4: Report Outage | C4: Transactional | D4: our whole block lost power | E4: route | F4: P01; P02; P03; P34; P35 | G4: 512-322-9100 OR text OUT to 287846 OR report online | I4: kept
A5: T004 | B5: Report Outage | C5: Transactional | D5: can you send someone my power went out | E5: route | F5: P01; P02; P03; P34; P35 | G5: 512-322-9100 OR text OUT to 287846 OR report online | I5: kept
A6: T005 | B6: Report Outage | C6: Transactional | D6: electricity is out where do i report it | E6: route | F6: P01; P02; P03; P34; P35 | G6: 512-322-9100 OR text OUT to 287846 OR report online | I6: kept
A7: T006 | B7: Report Outage | C7: Clean paraphrase | D7: what's the fastest way to let austin energy know my power is off | E7: answer | F7: P01; P02; P03; P34; P35 | G7: 512-322-9100 OR text OUT to 287846 OR report online | I7: kept
A8: T007 | B8: Report Outage | C8: Ambiguous | D8: nothing is working | E8: clarify | F8: P01; P02; P03; P34; P35 | G8: Asks whether it is a power outage; offers outage reporting | I8: kept
A9: T008 | B9: Report Outage | C9: Clean paraphrase | D9: who do i contact when the lights go out | E9: answer | F9: P01; P02; P03; P34; P35 | G9: 512-322-9100 | I9: kept
A10: T009 | B10: Report Outage | C10: Typos / slang | D10: pwr out cant get lights bak on | E10: answer | F10: P01; P02; P03; P34; P35 | G10: Check breakers if safe; report outage (512-322-9100 or text OUT to 287846) | I10: kept
A11: T010 | B11: Report Outage | C11: Clean paraphrase | D11: my neighborhood has no electricity | E11: answer | F11: P01; P02; P03; P34; P35 | G11: 512-322-9100 OR text OUT to 287846 OR report online; check the Outage Map | I11: kept
A12: T011 | B12: Check Outage Status | C12: Transactional | D12: check outage status | E12: route | F12: P02; P36 | G12: Outage Map | I12: kept
A13: T012 | B13: Check Outage Status | C13: Transactional | D13: is there a way to see when power will be back | E13: route | F13: P02; P36 | G13: Outage Map; estimated restoration time when available | I13: kept
... A35: T034 | B35: Understand My Bill | C35: Ambiguous | D35: why am i being charged so much | E35: clarify | F35: P06; P37; P11 | G35: Asks whether it is high usage, rates, or a suspected billing error | I35: kept
A36: T035 | B36: Understand My Bill | C36: Clean paraphrase | D36: what is the monthly customer charge | E36: answer | F36: P37 | G36: $17.35 per month | I36: edited | J36: what does psa mean on my bill | K36: Was a near repeat of T027 (both asked about the PSA)
A37: T036 | B37: Payment Options | C37: Typos / slang | D37: how i pay bill online | E37: answer | F37: P38; P07 | G37: Quick Payment online; $3.90 fee | I37: kept
A38: T037 | B38: Payment Options | C38: Clean paraphrase | D38: what ways can i pay my utility bill | E38: answer | F38: P07 | G38: Quick Payment online or by phone; Utility Customer Service Centers; authorized pay stations | I38: kept
A39: T038 | B39: Payment Options | C39: Spanish | D39: puedo pagar mi factura por internet | E39: answer | F39: P38; P07 | G39: Yes, Quick Payment online | I39: kept
A40: T039 | B40: Payment Options | C40: Clean paraphrase | D40: can i pay over the phone | E40: answer | F40: P38; P07 | G40: 1-833-375-4919 | I40: kept
A41: T040 | B41: Payment Options | C41: Ambiguous | D41: i need to make a payment | E41: clarify | F41: P07; P08 | G41: Asks whether they want to pay now or need more time (extension or arrangement) | I41: kept
A42: T041 | B42: Payment Arrangement | C42: Clean paraphrase | D42: can i split my bill into payments | E42: answer | F42: P08; P09 | G42: Payment arrangement spreads past due amount into monthly installments; 512-494-9400 | I42: kept
A43: T042 | B43: Payment Arrangement | C43: Typos / slang | D43: cant pay whole bill rn | E43: answer | F43: P08; P09 | G43: Payment arrangement or extension; call 512-494-9400 | I43: kept
A44: T043 | B44: Payment Arrangement | C44: Clean paraphrase | D44: do you offer payment plans | E44: answer | F44: P08; P09 | G44: Yes, payment arrangements; call 512-494-9400 or request online | I44: kept
A45: T044 | B45: Payment Arrangement | C45: Spanish | D45: necesito más tiempo para pagar mi factura | E45: answer | F45: P08; P09 | G45: Payment extension or arrangement; 512-494-9400 | I45: kept
A46: T045 | B46: Payment Arrangement | C46: Clean paraphrase | D46: can i request a payment plan online | E46: answer | F46: P08 | G46: Yes, log in to COA Utilities to request a 12 month payment arrangement | I46: edited | J46: how do i set up a payment arrangement | K46: Was almost word for word the KB card "How can I set up a payment arrangement?"
A47: T046 | B47: Collections | C47: Ambiguous | D47: i got a letter in the mail | E47: clarify | F47: P10; P29 | G47: Asks what the letter says (disconnection notice, bill, or possible scam) | I47: kept
A48: T047 | B48: Collections | C48: Clean paraphrase | D48: will they cut off my power if im a week late paying | E48: answer + offer human | F48: P10; P09 | G48: Mailed past due notice first; disconnection possible after stated date; call 512-494-9400 | I48: edited | J48: what happens if i don't pay my bill | K48: Was almost word for word the KB card "What happens if I don't pay my bill on time?"
A49: T048 | B49: Collections | C49: Typos / slang | D49: got disconnect notice wat now | E49: answer + offer human | F49: P10 | G49: Call Customer Care 512-494-9400; options like payment arrangement or assistance | I49: kept
A50: T049 | B50: Collections | C50: Clean paraphrase | D50: how do i keep my electricity from being shut off | E50: answer + offer human | F50: P10; P08 | G50: Pay or call 512-494-9400 about extension, arrangement, or financial assistance | I50: kept
A51: T050 | B51: Collections | C51: Spanish | D51: recibí un aviso de desconexión | E51: answer + offer human | F51: P10 | G51: Call Customer Care 512-494-9400 before the due date on the notice | I51: kept
A52: T051 | B52: Bill Dispute | C52: Transactional | D52: i think i was billed incorrectly | E52: route | F52: P11 | G52: Request an administrative review; 512-494-9400; within 90 days | I52: kept
A53: T052 | B53: Bill Dispute | C53: Transactional | D53: how do i dispute a charge | E53: route | F53: P11 | G53: Request an administrative review; 512-494-9400; within 90 days | I53: kept
A54: T053 | B54: Bill Dispute | C54: Clean paraphrase | D54: someone needs to review my bill | E54: answer + offer human | F54: P11 | G54: Administrative review through Customer Care 512-494-9400 | I54: kept
A55: T054 | B55: Bill Dispute | C55: Ambiguous | D55: this amount doesn't seem right | E55: clarify | F55: P11; P06 | G55: Asks which amount and why; mentions administrative review if they want to dispute | I55: kept
A56: T055 | B56: Bill Dispute | C56: Clean paraphrase | D56: how do i contest my electric bill | E56: answer + offer human | F56: P11 | G56: Administrative review within 90 days; then administrative hearing in writing within 30 days | I56: edited | J56: necesito disputar mi factura | K56: Row type is Clean paraphrase but query was in Spanish
A57: T056 | B57: CAP | C57: Typos / slang | D57: any hlp paying utilty bill | E57: answer | F57: P12; P13 | G57: CAP utility bill discounts; Plus 1 emergency help; 512-494-9400 | I57: edited | J57: is there help paying utility bills | K57: Row type is Typos but query had no typos
A58: T057 | B58: CAP | C58: Clean paraphrase | D58: i'm struggling to pay my electric bill | E58: answer | F58: P12 | G58: CAP bill discounts; Plus 1 emergency fund; 512-494-9400 | I58: kept
A59: T058 | B59: CAP | C59: Spanish | D59: hay programas de ayuda para personas de bajos ingresos | E59: answer | F59: P12; P13 | G59: CAP utility bill discounts; qualify through programs like Medicaid or SNAP | I59: edited | J59: tell me about customer assistance programs | K59: Row type is Spanish but query was in English
A60: T059 | B60: CAP | C60: Clean paraphrase | D60: do low income customers qualify for help | E60: answer | F60: P13 | G60: Enrolled in a qualifying program (Medicaid, SNAP, CHIP, etc.) or income under 200% of Federal Poverty Level | I60: kept
A61: T060 | B61: CAP | C61: Ambiguous | D61: can i get a discount | E61: clarify | F61: P13; P15; P20 | G61: Asks what kind (bill discount through CAP vs rebates on upgrades) | I61: edited | J61: can seniors get utility assistance | K61: Was not ambiguous ("can seniors get utility assistance" has one clear meaning)
...

Sheet Check Counts
A1: Intent group | B1: Target | C1: Rows in sheet
A2: Report Outage | B2: 10 | C2: =COUNTIF('Test Set'!B:B,A2) -> 10
A3: Check Outage Status | B3: 5 | C3: =COUNTIF('Test Set'!B:B,A3) -> 5
A4: Outage Alerts | B4: 5 | C4: =COUNTIF('Test Set'!B:B,A4) -> 5
A5: Downed Power Lines | B5: 5 | C5: =COUNTIF('Test Set'!B:B,A5) -> 5
A6: Understand My Bill | B6: 10 | C6: =COUNTIF('Test Set'!B:B,A6) -> 10
A7: Payment Options | B7: 5 | C7: =COUNTIF('Test Set'!B:B,A7) -> 5
A8: Payment Arrangement | B8: 5 | C8: =COUNTIF('Test Set'!B:B,A8) -> 5
A9: Collections | B9: 5 | C9: =COUNTIF('Test Set'!B:B,A9) -> 5
A10: Bill Dispute | B10: 5 | C10: =COUNTIF('Test Set'!B:B,A10) -> 5
A11: CAP | B11: 10 | C11: =COUNTIF('Test Set'!B:B,A11) -> 10
A12: Weatherization | B12: 5 | C12: =COUNTIF('Test Set'!B:B,A12) -> 5
A13: Rebates | B13: 10 | C13: =COUNTIF('Test Set'!B:B,A13) -> 10
... A21: Out-of-Scope | B21: 25 | C21: =COUNTIF('Test Set'!B:B,A21) -> 25
A23: Query type | B23: Target | C23: Rows in sheet
A24: Clean paraphrase | B24: 60 | C24: =COUNTIF('Test Set'!C:C,A24) -> 60
A25: Out-of-scope | B25: 25 | C25: =COUNTIF('Test Set'!C:C,A25) -> 25
A26: Ambiguous | B26: 20 | C26: =COUNTIF('Test Set'!C:C,A26) -> 20
A27: Typos / slang | B27: 15 | C27: =COUNTIF('Test Set'!C:C,A27) -> 15
A28: Transactional | B28: 15 | C28: =COUNTIF('Test Set'!C:C,A28) -> 15
A29: Spanish | B29: 15 | C29: =COUNTIF('Test Set'!C:C,A29) -> 15
A31: Queries written | B31: 150 | C31: =COUNTA('Test Set'!D2:D151) -> 150
